I'm sorry, but an uncaught exception occurred.

While running game code:
  File "game/script.rpy", line 199, in script
    с "Хех! Интересно там у вас…"
Exception: Sayer 'с' is not defined.

-- Full Traceback ------------------------------------------------------------

Full traceback:
  File "game/script.rpy", line 199, in script
    с "Хех! Интересно там у вас…"
  File "renpy/ast.py", line 681, in execute
    who = eval_who(self.who, self.who_fast)
  File "renpy/ast.py", line 574, in eval_who
    raise Exception("Sayer '%s' is not defined." % who)
Exception: Sayer 'с' is not defined.

Windows-10-10.0.19041
Ren'Py 7.4.8.1895
homework4 1.0
Mon Oct 11 20:31:08 2021
